<?xml version="1.0" encoding="UTF-8"?>
<testng-results skipped="0" failed="1" total="1" passed="0">
  <reporter-output>
    <line>
      <![CDATA[About to begin executing Test Fujji_UserCRUD]]>
    </line>
    <line>
      <![CDATA[Completed executing following method : AdhocTest.verifyRecords]]>
    </line>
  </reporter-output>
  <suite name="Adobe test full Master" duration-ms="38501" started-at="2016-04-01T10:21:28Z" finished-at="2016-04-01T10:22:06Z">
    <groups>
    </groups>
    <test name="Fujji_UserCRUD" duration-ms="38501" started-at="2016-04-01T10:21:28Z" finished-at="2016-04-01T10:22:06Z">
      <class name="adobe.adobeTesting.AdhocTest">
        <test-method status="FAIL" signature="verifyRecords()[pri:0, instance:adobe.adobeTesting.AdhocTest@17c1bced]" name="verifyRecords" duration-ms="38360" started-at="2016-04-01T15:51:28Z" finished-at="2016-04-01T15:52:06Z">
          <exception class="java.lang.AssertionError">
            <message>
              <![CDATA[please find the values that are not encrypted file location: E:\snow2\adobeTesting/AdobeResource/temp/tmp2.txt expected [true] but found [false]]]>
            </message>
            <full-stacktrace>
              <![CDATA[java.lang.AssertionError: please find the values that are not encrypted file location: E:\snow2\adobeTesting/AdobeResource/temp/tmp2.txt expected [true] but found [false]
	at org.testng.Assert.fail(Assert.java:94)
	at org.testng.Assert.failNotEquals(Assert.java:513)
	at org.testng.Assert.assertEqualsImpl(Assert.java:135)
	at org.testng.Assert.assertEquals(Assert.java:116)
	at org.testng.Assert.assertEquals(Assert.java:305)
	at com.ciphercloud.qa.util.AdhocUtil.pasteFromClpbrd(AdhocUtil.java:174)
	at adobe.adobeTesting.AdhocTest.verifyRecords(AdhocTest.java:37)
	at sun.reflect.NativeMethodAccessorImpl.invoke0(Native Method)
	at sun.reflect.NativeMethodAccessorImpl.invoke(Unknown Source)
	at sun.reflect.DelegatingMethodAccessorImpl.invoke(Unknown Source)
	at java.lang.reflect.Method.invoke(Unknown Source)
	at org.testng.internal.MethodInvocationHelper.invokeMethod(MethodInvocationHelper.java:86)
	at org.testng.internal.Invoker.invokeMethod(Invoker.java:645)
	at org.testng.internal.Invoker.invokeTestMethod(Invoker.java:822)
	at org.testng.internal.Invoker.invokeTestMethods(Invoker.java:1130)
	at org.testng.internal.TestMethodWorker.invokeTestMethods(TestMethodWorker.java:129)
	at org.testng.internal.TestMethodWorker.run(TestMethodWorker.java:112)
	at org.testng.TestRunner.privateRun(TestRunner.java:782)
	at org.testng.TestRunner.run(TestRunner.java:632)
	at org.testng.SuiteRunner.runTest(SuiteRunner.java:366)
	at org.testng.SuiteRunner.runSequentially(SuiteRunner.java:361)
	at org.testng.SuiteRunner.privateRun(SuiteRunner.java:319)
	at org.testng.SuiteRunner.run(SuiteRunner.java:268)
	at org.testng.SuiteRunnerWorker.runSuite(SuiteRunnerWorker.java:52)
	at org.testng.SuiteRunnerWorker.run(SuiteRunnerWorker.java:86)
	at org.testng.TestNG.runSuitesSequentially(TestNG.java:1244)
	at org.testng.TestNG.runSuitesLocally(TestNG.java:1169)
	at org.testng.TestNG.run(TestNG.java:1064)
	at org.testng.remote.RemoteTestNG.run(RemoteTestNG.java:113)
	at org.testng.remote.RemoteTestNG.initAndRun(RemoteTestNG.java:206)
	at org.testng.remote.RemoteTestNG.main(RemoteTestNG.java:177)
]]>
            </full-stacktrace>
          </exception> <!-- java.lang.AssertionError -->
          <reporter-output>
            <line>
              <![CDATA[Completed executing following method : AdhocTest.verifyRecords]]>
            </line>
          </reporter-output>
        </test-method> <!-- verifyRecords -->
      </class> <!-- adobe.adobeTesting.AdhocTest -->
    </test> <!-- Fujji_UserCRUD -->
  </suite> <!-- Adobe test full Master -->
</testng-results>
